[2023-02-26T13:32:49.665+0000] {taskinstance.py:1083} INFO - Dependencies all met for <TaskInstance: my_dag.choose_best_model scheduled__2023-02-25T00:00:00+00:00 [queued]>
[2023-02-26T13:32:49.670+0000] {taskinstance.py:1083} INFO - Dependencies all met for <TaskInstance: my_dag.choose_best_model scheduled__2023-02-25T00:00:00+00:00 [queued]>
[2023-02-26T13:32:49.671+0000] {taskinstance.py:1279} INFO - 
--------------------------------------------------------------------------------
[2023-02-26T13:32:49.671+0000] {taskinstance.py:1280} INFO - Starting attempt 1 of 1
[2023-02-26T13:32:49.672+0000] {taskinstance.py:1281} INFO - 
--------------------------------------------------------------------------------
[2023-02-26T13:32:49.680+0000] {taskinstance.py:1300} INFO - Executing <Task(BranchPythonOperator): choose_best_model> on 2023-02-25 00:00:00+00:00
[2023-02-26T13:32:49.683+0000] {standard_task_runner.py:55} INFO - Started process 8375 to run task
[2023-02-26T13:32:49.687+0000] {standard_task_runner.py:82} INFO - Running: ['***', 'tasks', 'run', 'my_dag', 'choose_best_model', 'scheduled__2023-02-25T00:00:00+00:00', '--job-id', '8', '--raw', '--subdir', 'DAGS_FOLDER/my_dag.py', '--cfg-path', '/tmp/tmp9n58i8wi']
[2023-02-26T13:32:49.688+0000] {standard_task_runner.py:83} INFO - Job 8: Subtask choose_best_model
[2023-02-26T13:32:49.739+0000] {task_command.py:388} INFO - Running <TaskInstance: my_dag.choose_best_model scheduled__2023-02-25T00:00:00+00:00 [running]> on host 8aab065f5efa
[2023-02-26T13:32:49.792+0000] {taskinstance.py:1509} INFO - Exporting the following env vars:
AIRFLOW_CTX_DAG_OWNER=***
AIRFLOW_CTX_DAG_ID=my_dag
AIRFLOW_CTX_TASK_ID=choose_best_model
AIRFLOW_CTX_EXECUTION_DATE=2023-02-25T00:00:00+00:00
AIRFLOW_CTX_TRY_NUMBER=1
AIRFLOW_CTX_DAG_RUN_ID=scheduled__2023-02-25T00:00:00+00:00
[2023-02-26T13:32:49.793+0000] {taskinstance.py:1768} ERROR - Task failed with exception
Traceback (most recent call last):
  File "/home/airflow/.local/lib/python3.7/site-packages/airflow/operators/python.py", line 210, in execute
    branch = super().execute(context)
  File "/home/airflow/.local/lib/python3.7/site-packages/airflow/operators/python.py", line 175, in execute
    return_value = self.execute_callable()
  File "/home/airflow/.local/lib/python3.7/site-packages/airflow/operators/python.py", line 192, in execute_callable
    return self.python_callable(*self.op_args, **self.op_kwargs)
  File "/opt/airflow/dags/my_dag.py", line 13, in _choose_best_model
    accuracies=ti.xcom.pull(task_ids=[
AttributeError: 'TaskInstance' object has no attribute 'xcom'
[2023-02-26T13:32:49.803+0000] {taskinstance.py:1323} INFO - Marking task as FAILED. dag_id=my_dag, task_id=choose_best_model, execution_date=20230225T000000, start_date=20230226T133249, end_date=20230226T133249
[2023-02-26T13:32:49.810+0000] {standard_task_runner.py:105} ERROR - Failed to execute job 8 for task choose_best_model ('TaskInstance' object has no attribute 'xcom'; 8375)
[2023-02-26T13:32:49.859+0000] {local_task_job.py:208} INFO - Task exited with return code 1
[2023-02-26T13:32:49.884+0000] {taskinstance.py:2578} INFO - 0 downstream tasks scheduled from follow-on schedule check
